Traceback (most recent call last):
  File "print_traceback_error.py", line 3, in <module>
    raise Exception('This is the error message.')
Exception: This is the error message.
